## 3.06 js: 错误调试

##### 1. 错误

try 语句测试代码块的错误。
throw 语句创建自定义错误。  
catch 语句处理错误。  
finally 语句在 try 和 catch 语句之后，无论是否有触发异常，该语句都会执行。

```
<body>

    <p>请输出一个 5 到 10 之间的数字:</p>

    <input id="demo" type="text">
    <button type="button" onclick="myFunction()">测试输入</button>
    <p id="message"></p>

<script>
    function myFunction() {
        var message, x;
        message = document.getElementById("message");
        message.innerHTML = "";
        x = document.getElementById("demo").value;
        try {
            if(x == "")  throw "值为空";
            if(isNaN(x)) throw "不是数字";
            x = Number(x);
            if(x < 5)    throw "太小";
            if(x > 10)   throw "太大";
        }
        catch(err) {
            message.innerHTML = "错误: " + err;
        }
        finally {
          document.getElementById("demo").value = "";
        }
    }
</script>
</body>

>>>
不管输入是否正确，输入框都会再输入后清空。
请输出一个 5 到 10 之间的数字:
测试输入: xxx
错误: 不是数字
```

##### 2. 调试

1\. console.log() 方法  
2\. 在要断点语句后写 debgger 关键字

利用浏览器的 f12 开发者调试窗口
